[2024-06-14T04:29:23.436+0000] {scheduler_job_runner.py:769} ERROR - Executor reports task instance <TaskInstance: ETL_toll_data.unzip_data scheduled__2024-06-12T00:00:00+00:00 [queued]> finished (failed) although the task says it's queued. (Info: None) Was the task killed externally?
