[2024-06-14T03:04:57.252+0000] {processor.py:161} INFO - Started process (PID=29) to work on /opt/airflow/dags/ETL_toll_data.py
[2024-06-14T03:04:57.254+0000] {processor.py:830} INFO - Processing file /opt/airflow/dags/ETL_toll_data.py for tasks to queue
[2024-06-14T03:04:57.258+0000] {logging_mixin.py:188} INFO - [2024-06-14T03:04:57.257+0000] {dagbag.py:545} INFO - Filling up the DagBag from /opt/airflow/dags/ETL_toll_data.py
[2024-06-14T03:04:59.755+0000] {processor.py:840} INFO - DAG(s) 'ETL_toll_data' retrieved from /opt/airflow/dags/ETL_toll_data.py
[2024-06-14T03:05:01.997+0000] {logging_mixin.py:188} INFO - [2024-06-14T03:05:01.995+0000] {dag.py:3096} INFO - Sync 1 DAGs
[2024-06-14T03:05:02.037+0000] {logging_mixin.py:188} INFO - [2024-06-14T03:05:02.037+0000] {dag.py:3954} INFO - Setting next_dagrun for ETL_toll_data to 2024-06-10 00:00:00+00:00, run_after=2024-06-11 00:00:00+00:00
[2024-06-14T03:05:02.077+0000] {processor.py:183} INFO - Processing /opt/airflow/dags/ETL_toll_data.py took 4.835 seconds
[2024-06-14T03:05:30.420+0000] {processor.py:161} INFO - Started process (PID=30) to work on /opt/airflow/dags/ETL_toll_data.py
[2024-06-14T03:05:30.423+0000] {processor.py:830} INFO - Processing file /opt/airflow/dags/ETL_toll_data.py for tasks to queue
[2024-06-14T03:05:30.434+0000] {logging_mixin.py:188} INFO - [2024-06-14T03:05:30.430+0000] {dagbag.py:545} INFO - Filling up the DagBag from /opt/airflow/dags/ETL_toll_data.py
[2024-06-14T03:05:32.230+0000] {processor.py:840} INFO - DAG(s) 'ETL_toll_data' retrieved from /opt/airflow/dags/ETL_toll_data.py
[2024-06-14T03:05:32.689+0000] {logging_mixin.py:188} INFO - [2024-06-14T03:05:32.689+0000] {dag.py:3096} INFO - Sync 1 DAGs
[2024-06-14T03:05:32.727+0000] {logging_mixin.py:188} INFO - [2024-06-14T03:05:32.727+0000] {dag.py:3954} INFO - Setting next_dagrun for ETL_toll_data to 2024-06-10 00:00:00+00:00, run_after=2024-06-11 00:00:00+00:00
[2024-06-14T03:05:32.753+0000] {processor.py:183} INFO - Processing /opt/airflow/dags/ETL_toll_data.py took 2.370 seconds
[2024-06-14T03:06:03.069+0000] {processor.py:161} INFO - Started process (PID=93) to work on /opt/airflow/dags/ETL_toll_data.py
[2024-06-14T03:06:03.071+0000] {processor.py:830} INFO - Processing file /opt/airflow/dags/ETL_toll_data.py for tasks to queue
[2024-06-14T03:06:03.073+0000] {logging_mixin.py:188} INFO - [2024-06-14T03:06:03.073+0000] {dagbag.py:545} INFO - Filling up the DagBag from /opt/airflow/dags/ETL_toll_data.py
[2024-06-14T03:06:03.638+0000] {processor.py:840} INFO - DAG(s) 'ETL_toll_data' retrieved from /opt/airflow/dags/ETL_toll_data.py
[2024-06-14T03:06:03.654+0000] {logging_mixin.py:188} INFO - [2024-06-14T03:06:03.654+0000] {dag.py:3096} INFO - Sync 1 DAGs
[2024-06-14T03:06:03.679+0000] {logging_mixin.py:188} INFO - [2024-06-14T03:06:03.679+0000] {dag.py:3954} INFO - Setting next_dagrun for ETL_toll_data to 2024-06-10 00:00:00+00:00, run_after=2024-06-11 00:00:00+00:00
[2024-06-14T03:06:03.707+0000] {processor.py:183} INFO - Processing /opt/airflow/dags/ETL_toll_data.py took 0.648 seconds
[2024-06-14T03:06:33.779+0000] {processor.py:161} INFO - Started process (PID=157) to work on /opt/airflow/dags/ETL_toll_data.py
[2024-06-14T03:06:33.780+0000] {processor.py:830} INFO - Processing file /opt/airflow/dags/ETL_toll_data.py for tasks to queue
[2024-06-14T03:06:33.782+0000] {logging_mixin.py:188} INFO - [2024-06-14T03:06:33.782+0000] {dagbag.py:545} INFO - Filling up the DagBag from /opt/airflow/dags/ETL_toll_data.py
[2024-06-14T03:06:34.747+0000] {processor.py:840} INFO - DAG(s) 'ETL_toll_data' retrieved from /opt/airflow/dags/ETL_toll_data.py
[2024-06-14T03:06:34.775+0000] {logging_mixin.py:188} INFO - [2024-06-14T03:06:34.774+0000] {dag.py:3096} INFO - Sync 1 DAGs
[2024-06-14T03:06:34.803+0000] {logging_mixin.py:188} INFO - [2024-06-14T03:06:34.803+0000] {dag.py:3954} INFO - Setting next_dagrun for ETL_toll_data to 2024-06-10 00:00:00+00:00, run_after=2024-06-11 00:00:00+00:00
[2024-06-14T03:06:35.618+0000] {processor.py:183} INFO - Processing /opt/airflow/dags/ETL_toll_data.py took 1.845 seconds
[2024-06-14T04:26:12.006+0000] {processor.py:161} INFO - Started process (PID=30) to work on /opt/airflow/dags/ETL_toll_data.py
[2024-06-14T04:26:12.009+0000] {processor.py:830} INFO - Processing file /opt/airflow/dags/ETL_toll_data.py for tasks to queue
[2024-06-14T04:26:12.013+0000] {logging_mixin.py:188} INFO - [2024-06-14T04:26:12.012+0000] {dagbag.py:545} INFO - Filling up the DagBag from /opt/airflow/dags/ETL_toll_data.py
[2024-06-14T04:26:13.751+0000] {processor.py:840} INFO - DAG(s) 'ETL_toll_data' retrieved from /opt/airflow/dags/ETL_toll_data.py
[2024-06-14T04:26:14.467+0000] {logging_mixin.py:188} INFO - [2024-06-14T04:26:14.466+0000] {override.py:1829} INFO - Created Permission View: can read on DAG:ETL_toll_data
[2024-06-14T04:26:14.485+0000] {logging_mixin.py:188} INFO - [2024-06-14T04:26:14.484+0000] {override.py:1829} INFO - Created Permission View: can edit on DAG:ETL_toll_data
[2024-06-14T04:26:14.494+0000] {logging_mixin.py:188} INFO - [2024-06-14T04:26:14.494+0000] {override.py:1829} INFO - Created Permission View: can delete on DAG:ETL_toll_data
[2024-06-14T04:26:14.500+0000] {logging_mixin.py:188} INFO - [2024-06-14T04:26:14.498+0000] {dag.py:3096} INFO - Sync 1 DAGs
[2024-06-14T04:26:14.518+0000] {logging_mixin.py:188} INFO - [2024-06-14T04:26:14.518+0000] {dag.py:3118} INFO - Creating ORM DAG for ETL_toll_data
[2024-06-14T04:26:14.532+0000] {logging_mixin.py:188} INFO - [2024-06-14T04:26:14.532+0000] {dag.py:3954} INFO - Setting next_dagrun for ETL_toll_data to 2024-06-10 00:00:00+00:00, run_after=2024-06-11 00:00:00+00:00
[2024-06-14T04:26:14.553+0000] {processor.py:183} INFO - Processing /opt/airflow/dags/ETL_toll_data.py took 2.555 seconds
[2024-06-14T04:26:44.687+0000] {processor.py:161} INFO - Started process (PID=95) to work on /opt/airflow/dags/ETL_toll_data.py
[2024-06-14T04:26:44.688+0000] {processor.py:830} INFO - Processing file /opt/airflow/dags/ETL_toll_data.py for tasks to queue
[2024-06-14T04:26:44.691+0000] {logging_mixin.py:188} INFO - [2024-06-14T04:26:44.690+0000] {dagbag.py:545} INFO - Filling up the DagBag from /opt/airflow/dags/ETL_toll_data.py
[2024-06-14T04:26:45.225+0000] {processor.py:840} INFO - DAG(s) 'ETL_toll_data' retrieved from /opt/airflow/dags/ETL_toll_data.py
[2024-06-14T04:26:45.329+0000] {logging_mixin.py:188} INFO - [2024-06-14T04:26:45.329+0000] {dag.py:3096} INFO - Sync 1 DAGs
[2024-06-14T04:26:45.352+0000] {logging_mixin.py:188} INFO - [2024-06-14T04:26:45.352+0000] {dag.py:3954} INFO - Setting next_dagrun for ETL_toll_data to 2024-06-10 00:00:00+00:00, run_after=2024-06-11 00:00:00+00:00
[2024-06-14T04:26:45.376+0000] {processor.py:183} INFO - Processing /opt/airflow/dags/ETL_toll_data.py took 0.695 seconds
[2024-06-14T04:27:16.295+0000] {processor.py:161} INFO - Started process (PID=156) to work on /opt/airflow/dags/ETL_toll_data.py
[2024-06-14T04:27:16.296+0000] {processor.py:830} INFO - Processing file /opt/airflow/dags/ETL_toll_data.py for tasks to queue
[2024-06-14T04:27:16.299+0000] {logging_mixin.py:188} INFO - [2024-06-14T04:27:16.298+0000] {dagbag.py:545} INFO - Filling up the DagBag from /opt/airflow/dags/ETL_toll_data.py
[2024-06-14T04:27:16.945+0000] {processor.py:840} INFO - DAG(s) 'ETL_toll_data' retrieved from /opt/airflow/dags/ETL_toll_data.py
[2024-06-14T04:27:17.028+0000] {logging_mixin.py:188} INFO - [2024-06-14T04:27:17.028+0000] {dag.py:3096} INFO - Sync 1 DAGs
[2024-06-14T04:27:17.046+0000] {logging_mixin.py:188} INFO - [2024-06-14T04:27:17.046+0000] {dag.py:3954} INFO - Setting next_dagrun for ETL_toll_data to 2024-06-10 00:00:00+00:00, run_after=2024-06-11 00:00:00+00:00
[2024-06-14T04:27:17.069+0000] {processor.py:183} INFO - Processing /opt/airflow/dags/ETL_toll_data.py took 0.780 seconds
[2024-06-14T04:27:47.303+0000] {processor.py:161} INFO - Started process (PID=220) to work on /opt/airflow/dags/ETL_toll_data.py
[2024-06-14T04:27:47.305+0000] {processor.py:830} INFO - Processing file /opt/airflow/dags/ETL_toll_data.py for tasks to queue
[2024-06-14T04:27:47.307+0000] {logging_mixin.py:188} INFO - [2024-06-14T04:27:47.306+0000] {dagbag.py:545} INFO - Filling up the DagBag from /opt/airflow/dags/ETL_toll_data.py
[2024-06-14T04:27:47.763+0000] {processor.py:840} INFO - DAG(s) 'ETL_toll_data' retrieved from /opt/airflow/dags/ETL_toll_data.py
[2024-06-14T04:27:47.782+0000] {logging_mixin.py:188} INFO - [2024-06-14T04:27:47.782+0000] {dag.py:3096} INFO - Sync 1 DAGs
[2024-06-14T04:27:47.802+0000] {logging_mixin.py:188} INFO - [2024-06-14T04:27:47.802+0000] {dag.py:3954} INFO - Setting next_dagrun for ETL_toll_data to 2024-06-10 00:00:00+00:00, run_after=2024-06-11 00:00:00+00:00
[2024-06-14T04:27:47.824+0000] {processor.py:183} INFO - Processing /opt/airflow/dags/ETL_toll_data.py took 0.526 seconds
[2024-06-14T04:28:18.244+0000] {processor.py:161} INFO - Started process (PID=281) to work on /opt/airflow/dags/ETL_toll_data.py
[2024-06-14T04:28:18.248+0000] {processor.py:830} INFO - Processing file /opt/airflow/dags/ETL_toll_data.py for tasks to queue
[2024-06-14T04:28:18.250+0000] {logging_mixin.py:188} INFO - [2024-06-14T04:28:18.250+0000] {dagbag.py:545} INFO - Filling up the DagBag from /opt/airflow/dags/ETL_toll_data.py
[2024-06-14T04:28:19.873+0000] {processor.py:840} INFO - DAG(s) 'ETL_toll_data' retrieved from /opt/airflow/dags/ETL_toll_data.py
[2024-06-14T04:28:19.891+0000] {logging_mixin.py:188} INFO - [2024-06-14T04:28:19.891+0000] {dag.py:3096} INFO - Sync 1 DAGs
[2024-06-14T04:28:19.916+0000] {logging_mixin.py:188} INFO - [2024-06-14T04:28:19.916+0000] {dag.py:3954} INFO - Setting next_dagrun for ETL_toll_data to 2024-06-10 00:00:00+00:00, run_after=2024-06-11 00:00:00+00:00
[2024-06-14T04:28:19.942+0000] {processor.py:183} INFO - Processing /opt/airflow/dags/ETL_toll_data.py took 1.707 seconds
[2024-06-14T04:29:23.711+0000] {processor.py:161} INFO - Started process (PID=354) to work on /opt/airflow/dags/ETL_toll_data.py
[2024-06-14T04:29:23.713+0000] {processor.py:830} INFO - Processing file /opt/airflow/dags/ETL_toll_data.py for tasks to queue
[2024-06-14T04:29:23.715+0000] {logging_mixin.py:188} INFO - [2024-06-14T04:29:23.715+0000] {dagbag.py:545} INFO - Filling up the DagBag from /opt/airflow/dags/ETL_toll_data.py
[2024-06-14T04:29:25.116+0000] {processor.py:840} INFO - DAG(s) 'ETL_toll_data' retrieved from /opt/airflow/dags/ETL_toll_data.py
[2024-06-14T04:29:25.134+0000] {logging_mixin.py:188} INFO - [2024-06-14T04:29:25.133+0000] {dag.py:3096} INFO - Sync 1 DAGs
[2024-06-14T04:29:25.153+0000] {logging_mixin.py:188} INFO - [2024-06-14T04:29:25.152+0000] {dag.py:3954} INFO - Setting next_dagrun for ETL_toll_data to 2024-06-14 00:00:00+00:00, run_after=2024-06-15 00:00:00+00:00
[2024-06-14T04:29:25.284+0000] {processor.py:183} INFO - Processing /opt/airflow/dags/ETL_toll_data.py took 1.579 seconds
[2024-06-14T04:29:56.020+0000] {processor.py:161} INFO - Started process (PID=421) to work on /opt/airflow/dags/ETL_toll_data.py
[2024-06-14T04:29:56.021+0000] {processor.py:830} INFO - Processing file /opt/airflow/dags/ETL_toll_data.py for tasks to queue
[2024-06-14T04:29:56.024+0000] {logging_mixin.py:188} INFO - [2024-06-14T04:29:56.024+0000] {dagbag.py:545} INFO - Filling up the DagBag from /opt/airflow/dags/ETL_toll_data.py
[2024-06-14T04:29:56.546+0000] {processor.py:840} INFO - DAG(s) 'ETL_toll_data' retrieved from /opt/airflow/dags/ETL_toll_data.py
[2024-06-14T04:29:56.566+0000] {logging_mixin.py:188} INFO - [2024-06-14T04:29:56.565+0000] {dag.py:3096} INFO - Sync 1 DAGs
[2024-06-14T04:29:56.588+0000] {logging_mixin.py:188} INFO - [2024-06-14T04:29:56.587+0000] {dag.py:3954} INFO - Setting next_dagrun for ETL_toll_data to 2024-06-14 00:00:00+00:00, run_after=2024-06-15 00:00:00+00:00
[2024-06-14T04:29:56.610+0000] {processor.py:183} INFO - Processing /opt/airflow/dags/ETL_toll_data.py took 0.597 seconds
[2024-06-14T04:30:26.750+0000] {processor.py:161} INFO - Started process (PID=489) to work on /opt/airflow/dags/ETL_toll_data.py
[2024-06-14T04:30:26.757+0000] {processor.py:830} INFO - Processing file /opt/airflow/dags/ETL_toll_data.py for tasks to queue
[2024-06-14T04:30:26.760+0000] {logging_mixin.py:188} INFO - [2024-06-14T04:30:26.759+0000] {dagbag.py:545} INFO - Filling up the DagBag from /opt/airflow/dags/ETL_toll_data.py
[2024-06-14T04:30:43.149+0000] {processor.py:840} INFO - DAG(s) 'ETL_toll_data' retrieved from /opt/airflow/dags/ETL_toll_data.py
[2024-06-14T04:30:43.184+0000] {logging_mixin.py:188} INFO - [2024-06-14T04:30:43.183+0000] {dag.py:3096} INFO - Sync 1 DAGs
[2024-06-14T04:30:43.214+0000] {logging_mixin.py:188} INFO - [2024-06-14T04:30:43.214+0000] {dag.py:3954} INFO - Setting next_dagrun for ETL_toll_data to 2024-06-14 00:00:00+00:00, run_after=2024-06-15 00:00:00+00:00
[2024-06-14T04:30:43.241+0000] {processor.py:183} INFO - Processing /opt/airflow/dags/ETL_toll_data.py took 16.499 seconds
[2024-06-14T04:30:53.038+0000] {processor.py:161} INFO - Started process (PID=545) to work on /opt/airflow/dags/ETL_toll_data.py
[2024-06-14T04:30:53.039+0000] {processor.py:830} INFO - Processing file /opt/airflow/dags/ETL_toll_data.py for tasks to queue
[2024-06-14T04:30:53.041+0000] {logging_mixin.py:188} INFO - [2024-06-14T04:30:53.041+0000] {dagbag.py:545} INFO - Filling up the DagBag from /opt/airflow/dags/ETL_toll_data.py
[2024-06-14T04:30:53.508+0000] {processor.py:840} INFO - DAG(s) 'ETL_toll_data' retrieved from /opt/airflow/dags/ETL_toll_data.py
[2024-06-14T04:30:53.527+0000] {logging_mixin.py:188} INFO - [2024-06-14T04:30:53.527+0000] {taskinstance.py:2907} ERROR - {'DAG Id': 'ETL_toll_data', 'Task Id': 'unzip_data', 'Run Id': 'scheduled__2024-06-11T00:00:00+00:00', 'Hostname': 'af8e208997f1', 'External Executor Id': '147dca8d-77f4-45a3-b69a-2eb820b670c2'}
[2024-06-14T04:30:53.543+0000] {logging_mixin.py:188} INFO - [2024-06-14T04:30:53.543+0000] {taskinstance.py:1206} INFO - Marking task as FAILED. dag_id=ETL_toll_data, task_id=unzip_data, run_id=scheduled__2024-06-11T00:00:00+00:00, execution_date=20240611T000000, start_date=20240614T043027, end_date=20240614T043053
[2024-06-14T04:30:53.562+0000] {logging_mixin.py:188} WARNING - /home/airflow/.local/lib/python3.12/site-packages/airflow/utils/email.py:154 RemovedInAirflow3Warning: Fetching SMTP credentials from configuration variables will be deprecated in a future release. Please set credentials using a connection instead.
[2024-06-14T04:30:53.563+0000] {logging_mixin.py:188} INFO - [2024-06-14T04:30:53.563+0000] {configuration.py:1050} WARNING - section/key [smtp/smtp_user] not found in config
[2024-06-14T04:30:53.564+0000] {logging_mixin.py:188} INFO - [2024-06-14T04:30:53.563+0000] {email.py:271} INFO - Email alerting: attempt 1
[2024-06-14T04:30:53.569+0000] {logging_mixin.py:188} INFO - [2024-06-14T04:30:53.569+0000] {configuration.py:1050} WARNING - section/key [smtp/smtp_user] not found in config
[2024-06-14T04:30:53.569+0000] {logging_mixin.py:188} INFO - [2024-06-14T04:30:53.569+0000] {email.py:271} INFO - Email alerting: attempt 1
[2024-06-14T04:30:53.573+0000] {logging_mixin.py:188} INFO - [2024-06-14T04:30:53.570+0000] {taskinstance.py:879} ERROR - Failed to send email to: ['21521333@gm.uit.edu.vn']
Traceback (most recent call last):
  File "/home/airflow/.local/lib/python3.12/site-packages/airflow/models/taskinstance.py", line 1063, in _email_alert
    send_email(task.email, subject, html_content)
  File "/home/airflow/.local/lib/python3.12/site-packages/airflow/utils/email.py", line 80, in send_email
    return backend(
           ^^^^^^^^
  File "/home/airflow/.local/lib/python3.12/site-packages/airflow/utils/email.py", line 154, in send_email_smtp
    send_mime_email(e_from=mail_from, e_to=recipients, mime_msg=msg, conn_id=conn_id, dryrun=dryrun)
  File "/home/airflow/.local/lib/python3.12/site-packages/airflow/utils/email.py", line 273, in send_mime_email
    smtp_conn = _get_smtp_connection(smtp_host, smtp_port, smtp_timeout, smtp_ssl)
                ^^^^^^^^^^^^^^^^^^^^^^^^^^^^^^^^^^^^^^^^^^^^^^^^^^^^^^^^^^^^^^^^^^
  File "/home/airflow/.local/lib/python3.12/site-packages/airflow/utils/email.py", line 317, in _get_smtp_connection
    return smtplib.SMTP(host=host, port=port, timeout=timeout)
           ^^^^^^^^^^^^^^^^^^^^^^^^^^^^^^^^^^^^^^^^^^^^^^^^^^^
  File "/usr/local/lib/python3.12/smtplib.py", line 255, in __init__
    (code, msg) = self.connect(host, port)
                  ^^^^^^^^^^^^^^^^^^^^^^^^
  File "/usr/local/lib/python3.12/smtplib.py", line 341, in connect
    self.sock = self._get_socket(host, port, self.timeout)
                ^^^^^^^^^^^^^^^^^^^^^^^^^^^^^^^^^^^^^^^^^^
  File "/usr/local/lib/python3.12/smtplib.py", line 312, in _get_socket
    return socket.create_connection((host, port), timeout,
           ^^^^^^^^^^^^^^^^^^^^^^^^^^^^^^^^^^^^^^^^^^^^^^^
  File "/usr/local/lib/python3.12/socket.py", line 853, in create_connection
    raise exceptions[0]
  File "/usr/local/lib/python3.12/socket.py", line 838, in create_connection
    sock.connect(sa)
ConnectionRefusedError: [Errno 111] Connection refused

During handling of the above exception, another exception occurred:

Traceback (most recent call last):
  File "/home/airflow/.local/lib/python3.12/site-packages/airflow/models/taskinstance.py", line 877, in _handle_failure
    task_instance.email_alert(error, failure_context["task"])
  File "/home/airflow/.local/lib/python3.12/site-packages/airflow/models/taskinstance.py", line 3163, in email_alert
    _email_alert(task_instance=self, exception=exception, task=task)
  File "/home/airflow/.local/lib/python3.12/site-packages/airflow/models/taskinstance.py", line 1065, in _email_alert
    send_email(task.email, subject, html_content_err)
  File "/home/airflow/.local/lib/python3.12/site-packages/airflow/utils/email.py", line 80, in send_email
    return backend(
           ^^^^^^^^
  File "/home/airflow/.local/lib/python3.12/site-packages/airflow/utils/email.py", line 154, in send_email_smtp
    send_mime_email(e_from=mail_from, e_to=recipients, mime_msg=msg, conn_id=conn_id, dryrun=dryrun)
  File "/home/airflow/.local/lib/python3.12/site-packages/airflow/utils/email.py", line 273, in send_mime_email
    smtp_conn = _get_smtp_connection(smtp_host, smtp_port, smtp_timeout, smtp_ssl)
                ^^^^^^^^^^^^^^^^^^^^^^^^^^^^^^^^^^^^^^^^^^^^^^^^^^^^^^^^^^^^^^^^^^
  File "/home/airflow/.local/lib/python3.12/site-packages/airflow/utils/email.py", line 317, in _get_smtp_connection
    return smtplib.SMTP(host=host, port=port, timeout=timeout)
           ^^^^^^^^^^^^^^^^^^^^^^^^^^^^^^^^^^^^^^^^^^^^^^^^^^^
  File "/usr/local/lib/python3.12/smtplib.py", line 255, in __init__
    (code, msg) = self.connect(host, port)
                  ^^^^^^^^^^^^^^^^^^^^^^^^
  File "/usr/local/lib/python3.12/smtplib.py", line 341, in connect
    self.sock = self._get_socket(host, port, self.timeout)
                ^^^^^^^^^^^^^^^^^^^^^^^^^^^^^^^^^^^^^^^^^^
  File "/usr/local/lib/python3.12/smtplib.py", line 312, in _get_socket
    return socket.create_connection((host, port), timeout,
           ^^^^^^^^^^^^^^^^^^^^^^^^^^^^^^^^^^^^^^^^^^^^^^^
  File "/usr/local/lib/python3.12/socket.py", line 853, in create_connection
    raise exceptions[0]
  File "/usr/local/lib/python3.12/socket.py", line 838, in create_connection
    sock.connect(sa)
ConnectionRefusedError: [Errno 111] Connection refused
[2024-06-14T04:30:53.587+0000] {processor.py:791} INFO - Executed failure callback for <TaskInstance: ETL_toll_data.unzip_data scheduled__2024-06-11T00:00:00+00:00 [failed]> in state failed
[2024-06-14T04:30:53.606+0000] {logging_mixin.py:188} INFO - [2024-06-14T04:30:53.606+0000] {dag.py:3096} INFO - Sync 1 DAGs
[2024-06-14T04:30:53.625+0000] {logging_mixin.py:188} INFO - [2024-06-14T04:30:53.625+0000] {dag.py:3954} INFO - Setting next_dagrun for ETL_toll_data to 2024-06-14 00:00:00+00:00, run_after=2024-06-15 00:00:00+00:00
[2024-06-14T04:30:53.656+0000] {processor.py:183} INFO - Processing /opt/airflow/dags/ETL_toll_data.py took 0.626 seconds
[2024-06-14T04:31:03.163+0000] {processor.py:161} INFO - Started process (PID=572) to work on /opt/airflow/dags/ETL_toll_data.py
[2024-06-14T04:31:03.164+0000] {processor.py:830} INFO - Processing file /opt/airflow/dags/ETL_toll_data.py for tasks to queue
[2024-06-14T04:31:03.166+0000] {logging_mixin.py:188} INFO - [2024-06-14T04:31:03.166+0000] {dagbag.py:545} INFO - Filling up the DagBag from /opt/airflow/dags/ETL_toll_data.py
[2024-06-14T04:31:03.682+0000] {processor.py:840} INFO - DAG(s) 'ETL_toll_data' retrieved from /opt/airflow/dags/ETL_toll_data.py
[2024-06-14T04:31:03.703+0000] {logging_mixin.py:188} INFO - [2024-06-14T04:31:03.702+0000] {taskinstance.py:2907} ERROR - {'DAG Id': 'ETL_toll_data', 'Task Id': 'unzip_data', 'Run Id': 'scheduled__2024-06-12T00:00:00+00:00', 'Hostname': 'af8e208997f1', 'External Executor Id': 'e1f5c2f7-18f6-4ef5-b6f5-e1d04ab2d854'}
[2024-06-14T04:31:03.719+0000] {logging_mixin.py:188} INFO - [2024-06-14T04:31:03.719+0000] {taskinstance.py:1206} INFO - Marking task as FAILED. dag_id=ETL_toll_data, task_id=unzip_data, run_id=scheduled__2024-06-12T00:00:00+00:00, execution_date=20240612T000000, start_date=20240614T043027, end_date=20240614T043103
[2024-06-14T04:31:03.737+0000] {logging_mixin.py:188} WARNING - /home/airflow/.local/lib/python3.12/site-packages/airflow/utils/email.py:154 RemovedInAirflow3Warning: Fetching SMTP credentials from configuration variables will be deprecated in a future release. Please set credentials using a connection instead.
[2024-06-14T04:31:03.738+0000] {logging_mixin.py:188} INFO - [2024-06-14T04:31:03.738+0000] {configuration.py:1050} WARNING - section/key [smtp/smtp_user] not found in config
[2024-06-14T04:31:03.738+0000] {logging_mixin.py:188} INFO - [2024-06-14T04:31:03.738+0000] {email.py:271} INFO - Email alerting: attempt 1
[2024-06-14T04:31:03.742+0000] {logging_mixin.py:188} INFO - [2024-06-14T04:31:03.742+0000] {configuration.py:1050} WARNING - section/key [smtp/smtp_user] not found in config
[2024-06-14T04:31:03.743+0000] {logging_mixin.py:188} INFO - [2024-06-14T04:31:03.743+0000] {email.py:271} INFO - Email alerting: attempt 1
[2024-06-14T04:31:03.746+0000] {logging_mixin.py:188} INFO - [2024-06-14T04:31:03.744+0000] {taskinstance.py:879} ERROR - Failed to send email to: ['21521333@gm.uit.edu.vn']
Traceback (most recent call last):
  File "/home/airflow/.local/lib/python3.12/site-packages/airflow/models/taskinstance.py", line 1063, in _email_alert
    send_email(task.email, subject, html_content)
  File "/home/airflow/.local/lib/python3.12/site-packages/airflow/utils/email.py", line 80, in send_email
    return backend(
           ^^^^^^^^
  File "/home/airflow/.local/lib/python3.12/site-packages/airflow/utils/email.py", line 154, in send_email_smtp
    send_mime_email(e_from=mail_from, e_to=recipients, mime_msg=msg, conn_id=conn_id, dryrun=dryrun)
  File "/home/airflow/.local/lib/python3.12/site-packages/airflow/utils/email.py", line 273, in send_mime_email
    smtp_conn = _get_smtp_connection(smtp_host, smtp_port, smtp_timeout, smtp_ssl)
                ^^^^^^^^^^^^^^^^^^^^^^^^^^^^^^^^^^^^^^^^^^^^^^^^^^^^^^^^^^^^^^^^^^
  File "/home/airflow/.local/lib/python3.12/site-packages/airflow/utils/email.py", line 317, in _get_smtp_connection
    return smtplib.SMTP(host=host, port=port, timeout=timeout)
           ^^^^^^^^^^^^^^^^^^^^^^^^^^^^^^^^^^^^^^^^^^^^^^^^^^^
  File "/usr/local/lib/python3.12/smtplib.py", line 255, in __init__
    (code, msg) = self.connect(host, port)
                  ^^^^^^^^^^^^^^^^^^^^^^^^
  File "/usr/local/lib/python3.12/smtplib.py", line 341, in connect
    self.sock = self._get_socket(host, port, self.timeout)
                ^^^^^^^^^^^^^^^^^^^^^^^^^^^^^^^^^^^^^^^^^^
  File "/usr/local/lib/python3.12/smtplib.py", line 312, in _get_socket
    return socket.create_connection((host, port), timeout,
           ^^^^^^^^^^^^^^^^^^^^^^^^^^^^^^^^^^^^^^^^^^^^^^^
  File "/usr/local/lib/python3.12/socket.py", line 853, in create_connection
    raise exceptions[0]
  File "/usr/local/lib/python3.12/socket.py", line 838, in create_connection
    sock.connect(sa)
ConnectionRefusedError: [Errno 111] Connection refused

During handling of the above exception, another exception occurred:

Traceback (most recent call last):
  File "/home/airflow/.local/lib/python3.12/site-packages/airflow/models/taskinstance.py", line 877, in _handle_failure
    task_instance.email_alert(error, failure_context["task"])
  File "/home/airflow/.local/lib/python3.12/site-packages/airflow/models/taskinstance.py", line 3163, in email_alert
    _email_alert(task_instance=self, exception=exception, task=task)
  File "/home/airflow/.local/lib/python3.12/site-packages/airflow/models/taskinstance.py", line 1065, in _email_alert
    send_email(task.email, subject, html_content_err)
  File "/home/airflow/.local/lib/python3.12/site-packages/airflow/utils/email.py", line 80, in send_email
    return backend(
           ^^^^^^^^
  File "/home/airflow/.local/lib/python3.12/site-packages/airflow/utils/email.py", line 154, in send_email_smtp
    send_mime_email(e_from=mail_from, e_to=recipients, mime_msg=msg, conn_id=conn_id, dryrun=dryrun)
  File "/home/airflow/.local/lib/python3.12/site-packages/airflow/utils/email.py", line 273, in send_mime_email
    smtp_conn = _get_smtp_connection(smtp_host, smtp_port, smtp_timeout, smtp_ssl)
                ^^^^^^^^^^^^^^^^^^^^^^^^^^^^^^^^^^^^^^^^^^^^^^^^^^^^^^^^^^^^^^^^^^
  File "/home/airflow/.local/lib/python3.12/site-packages/airflow/utils/email.py", line 317, in _get_smtp_connection
    return smtplib.SMTP(host=host, port=port, timeout=timeout)
           ^^^^^^^^^^^^^^^^^^^^^^^^^^^^^^^^^^^^^^^^^^^^^^^^^^^
  File "/usr/local/lib/python3.12/smtplib.py", line 255, in __init__
    (code, msg) = self.connect(host, port)
                  ^^^^^^^^^^^^^^^^^^^^^^^^
  File "/usr/local/lib/python3.12/smtplib.py", line 341, in connect
    self.sock = self._get_socket(host, port, self.timeout)
                ^^^^^^^^^^^^^^^^^^^^^^^^^^^^^^^^^^^^^^^^^^
  File "/usr/local/lib/python3.12/smtplib.py", line 312, in _get_socket
    return socket.create_connection((host, port), timeout,
           ^^^^^^^^^^^^^^^^^^^^^^^^^^^^^^^^^^^^^^^^^^^^^^^
  File "/usr/local/lib/python3.12/socket.py", line 853, in create_connection
    raise exceptions[0]
  File "/usr/local/lib/python3.12/socket.py", line 838, in create_connection
    sock.connect(sa)
ConnectionRefusedError: [Errno 111] Connection refused
[2024-06-14T04:31:03.757+0000] {processor.py:791} INFO - Executed failure callback for <TaskInstance: ETL_toll_data.unzip_data scheduled__2024-06-12T00:00:00+00:00 [failed]> in state failed
[2024-06-14T04:31:03.760+0000] {logging_mixin.py:188} INFO - [2024-06-14T04:31:03.760+0000] {taskinstance.py:2907} ERROR - {'DAG Id': 'ETL_toll_data', 'Task Id': 'unzip_data', 'Run Id': 'scheduled__2024-06-10T00:00:00+00:00', 'Hostname': 'af8e208997f1', 'External Executor Id': '0b103bb7-eab8-4be7-aa9a-ca7c018b611c'}
[2024-06-14T04:31:03.767+0000] {logging_mixin.py:188} INFO - [2024-06-14T04:31:03.766+0000] {taskinstance.py:1206} INFO - Marking task as FAILED. dag_id=ETL_toll_data, task_id=unzip_data, run_id=scheduled__2024-06-10T00:00:00+00:00, execution_date=20240610T000000, start_date=20240614T043027, end_date=20240614T043103
[2024-06-14T04:31:03.779+0000] {logging_mixin.py:188} WARNING - /home/airflow/.local/lib/python3.12/site-packages/airflow/utils/email.py:154 RemovedInAirflow3Warning: Fetching SMTP credentials from configuration variables will be deprecated in a future release. Please set credentials using a connection instead.
[2024-06-14T04:31:03.780+0000] {logging_mixin.py:188} INFO - [2024-06-14T04:31:03.780+0000] {configuration.py:1050} WARNING - section/key [smtp/smtp_user] not found in config
[2024-06-14T04:31:03.780+0000] {logging_mixin.py:188} INFO - [2024-06-14T04:31:03.780+0000] {email.py:271} INFO - Email alerting: attempt 1
[2024-06-14T04:31:03.783+0000] {logging_mixin.py:188} INFO - [2024-06-14T04:31:03.783+0000] {configuration.py:1050} WARNING - section/key [smtp/smtp_user] not found in config
[2024-06-14T04:31:03.784+0000] {logging_mixin.py:188} INFO - [2024-06-14T04:31:03.784+0000] {email.py:271} INFO - Email alerting: attempt 1
[2024-06-14T04:31:03.786+0000] {logging_mixin.py:188} INFO - [2024-06-14T04:31:03.784+0000] {taskinstance.py:879} ERROR - Failed to send email to: ['21521333@gm.uit.edu.vn']
Traceback (most recent call last):
  File "/home/airflow/.local/lib/python3.12/site-packages/airflow/models/taskinstance.py", line 1063, in _email_alert
    send_email(task.email, subject, html_content)
  File "/home/airflow/.local/lib/python3.12/site-packages/airflow/utils/email.py", line 80, in send_email
    return backend(
           ^^^^^^^^
  File "/home/airflow/.local/lib/python3.12/site-packages/airflow/utils/email.py", line 154, in send_email_smtp
    send_mime_email(e_from=mail_from, e_to=recipients, mime_msg=msg, conn_id=conn_id, dryrun=dryrun)
  File "/home/airflow/.local/lib/python3.12/site-packages/airflow/utils/email.py", line 273, in send_mime_email
    smtp_conn = _get_smtp_connection(smtp_host, smtp_port, smtp_timeout, smtp_ssl)
                ^^^^^^^^^^^^^^^^^^^^^^^^^^^^^^^^^^^^^^^^^^^^^^^^^^^^^^^^^^^^^^^^^^
  File "/home/airflow/.local/lib/python3.12/site-packages/airflow/utils/email.py", line 317, in _get_smtp_connection
    return smtplib.SMTP(host=host, port=port, timeout=timeout)
           ^^^^^^^^^^^^^^^^^^^^^^^^^^^^^^^^^^^^^^^^^^^^^^^^^^^
  File "/usr/local/lib/python3.12/smtplib.py", line 255, in __init__
    (code, msg) = self.connect(host, port)
                  ^^^^^^^^^^^^^^^^^^^^^^^^
  File "/usr/local/lib/python3.12/smtplib.py", line 341, in connect
    self.sock = self._get_socket(host, port, self.timeout)
                ^^^^^^^^^^^^^^^^^^^^^^^^^^^^^^^^^^^^^^^^^^
  File "/usr/local/lib/python3.12/smtplib.py", line 312, in _get_socket
    return socket.create_connection((host, port), timeout,
           ^^^^^^^^^^^^^^^^^^^^^^^^^^^^^^^^^^^^^^^^^^^^^^^
  File "/usr/local/lib/python3.12/socket.py", line 853, in create_connection
    raise exceptions[0]
  File "/usr/local/lib/python3.12/socket.py", line 838, in create_connection
    sock.connect(sa)
ConnectionRefusedError: [Errno 111] Connection refused

During handling of the above exception, another exception occurred:

Traceback (most recent call last):
  File "/home/airflow/.local/lib/python3.12/site-packages/airflow/models/taskinstance.py", line 877, in _handle_failure
    task_instance.email_alert(error, failure_context["task"])
  File "/home/airflow/.local/lib/python3.12/site-packages/airflow/models/taskinstance.py", line 3163, in email_alert
    _email_alert(task_instance=self, exception=exception, task=task)
  File "/home/airflow/.local/lib/python3.12/site-packages/airflow/models/taskinstance.py", line 1065, in _email_alert
    send_email(task.email, subject, html_content_err)
  File "/home/airflow/.local/lib/python3.12/site-packages/airflow/utils/email.py", line 80, in send_email
    return backend(
           ^^^^^^^^
  File "/home/airflow/.local/lib/python3.12/site-packages/airflow/utils/email.py", line 154, in send_email_smtp
    send_mime_email(e_from=mail_from, e_to=recipients, mime_msg=msg, conn_id=conn_id, dryrun=dryrun)
  File "/home/airflow/.local/lib/python3.12/site-packages/airflow/utils/email.py", line 273, in send_mime_email
    smtp_conn = _get_smtp_connection(smtp_host, smtp_port, smtp_timeout, smtp_ssl)
                ^^^^^^^^^^^^^^^^^^^^^^^^^^^^^^^^^^^^^^^^^^^^^^^^^^^^^^^^^^^^^^^^^^
  File "/home/airflow/.local/lib/python3.12/site-packages/airflow/utils/email.py", line 317, in _get_smtp_connection
    return smtplib.SMTP(host=host, port=port, timeout=timeout)
           ^^^^^^^^^^^^^^^^^^^^^^^^^^^^^^^^^^^^^^^^^^^^^^^^^^^
  File "/usr/local/lib/python3.12/smtplib.py", line 255, in __init__
    (code, msg) = self.connect(host, port)
                  ^^^^^^^^^^^^^^^^^^^^^^^^
  File "/usr/local/lib/python3.12/smtplib.py", line 341, in connect
    self.sock = self._get_socket(host, port, self.timeout)
                ^^^^^^^^^^^^^^^^^^^^^^^^^^^^^^^^^^^^^^^^^^
  File "/usr/local/lib/python3.12/smtplib.py", line 312, in _get_socket
    return socket.create_connection((host, port), timeout,
           ^^^^^^^^^^^^^^^^^^^^^^^^^^^^^^^^^^^^^^^^^^^^^^^
  File "/usr/local/lib/python3.12/socket.py", line 853, in create_connection
    raise exceptions[0]
  File "/usr/local/lib/python3.12/socket.py", line 838, in create_connection
    sock.connect(sa)
ConnectionRefusedError: [Errno 111] Connection refused
[2024-06-14T04:31:03.789+0000] {processor.py:791} INFO - Executed failure callback for <TaskInstance: ETL_toll_data.unzip_data scheduled__2024-06-10T00:00:00+00:00 [failed]> in state failed
[2024-06-14T04:31:03.792+0000] {logging_mixin.py:188} INFO - [2024-06-14T04:31:03.791+0000] {taskinstance.py:2907} ERROR - {'DAG Id': 'ETL_toll_data', 'Task Id': 'unzip_data', 'Run Id': 'scheduled__2024-06-12T00:00:00+00:00', 'Hostname': 'af8e208997f1', 'External Executor Id': 'e1f5c2f7-18f6-4ef5-b6f5-e1d04ab2d854'}
[2024-06-14T04:31:03.798+0000] {logging_mixin.py:188} INFO - [2024-06-14T04:31:03.798+0000] {taskinstance.py:1206} INFO - Marking task as FAILED. dag_id=ETL_toll_data, task_id=unzip_data, run_id=scheduled__2024-06-12T00:00:00+00:00, execution_date=20240612T000000, start_date=20240614T043027, end_date=20240614T043103
[2024-06-14T04:31:03.809+0000] {logging_mixin.py:188} WARNING - /home/airflow/.local/lib/python3.12/site-packages/airflow/utils/email.py:154 RemovedInAirflow3Warning: Fetching SMTP credentials from configuration variables will be deprecated in a future release. Please set credentials using a connection instead.
[2024-06-14T04:31:03.810+0000] {logging_mixin.py:188} INFO - [2024-06-14T04:31:03.810+0000] {configuration.py:1050} WARNING - section/key [smtp/smtp_user] not found in config
[2024-06-14T04:31:03.811+0000] {logging_mixin.py:188} INFO - [2024-06-14T04:31:03.810+0000] {email.py:271} INFO - Email alerting: attempt 1
[2024-06-14T04:31:03.815+0000] {logging_mixin.py:188} INFO - [2024-06-14T04:31:03.815+0000] {configuration.py:1050} WARNING - section/key [smtp/smtp_user] not found in config
[2024-06-14T04:31:03.816+0000] {logging_mixin.py:188} INFO - [2024-06-14T04:31:03.816+0000] {email.py:271} INFO - Email alerting: attempt 1
[2024-06-14T04:31:03.819+0000] {logging_mixin.py:188} INFO - [2024-06-14T04:31:03.817+0000] {taskinstance.py:879} ERROR - Failed to send email to: ['21521333@gm.uit.edu.vn']
Traceback (most recent call last):
  File "/home/airflow/.local/lib/python3.12/site-packages/airflow/models/taskinstance.py", line 1063, in _email_alert
    send_email(task.email, subject, html_content)
  File "/home/airflow/.local/lib/python3.12/site-packages/airflow/utils/email.py", line 80, in send_email
    return backend(
           ^^^^^^^^
  File "/home/airflow/.local/lib/python3.12/site-packages/airflow/utils/email.py", line 154, in send_email_smtp
    send_mime_email(e_from=mail_from, e_to=recipients, mime_msg=msg, conn_id=conn_id, dryrun=dryrun)
  File "/home/airflow/.local/lib/python3.12/site-packages/airflow/utils/email.py", line 273, in send_mime_email
    smtp_conn = _get_smtp_connection(smtp_host, smtp_port, smtp_timeout, smtp_ssl)
                ^^^^^^^^^^^^^^^^^^^^^^^^^^^^^^^^^^^^^^^^^^^^^^^^^^^^^^^^^^^^^^^^^^
  File "/home/airflow/.local/lib/python3.12/site-packages/airflow/utils/email.py", line 317, in _get_smtp_connection
    return smtplib.SMTP(host=host, port=port, timeout=timeout)
           ^^^^^^^^^^^^^^^^^^^^^^^^^^^^^^^^^^^^^^^^^^^^^^^^^^^
  File "/usr/local/lib/python3.12/smtplib.py", line 255, in __init__
    (code, msg) = self.connect(host, port)
                  ^^^^^^^^^^^^^^^^^^^^^^^^
  File "/usr/local/lib/python3.12/smtplib.py", line 341, in connect
    self.sock = self._get_socket(host, port, self.timeout)
                ^^^^^^^^^^^^^^^^^^^^^^^^^^^^^^^^^^^^^^^^^^
  File "/usr/local/lib/python3.12/smtplib.py", line 312, in _get_socket
    return socket.create_connection((host, port), timeout,
           ^^^^^^^^^^^^^^^^^^^^^^^^^^^^^^^^^^^^^^^^^^^^^^^
  File "/usr/local/lib/python3.12/socket.py", line 853, in create_connection
    raise exceptions[0]
  File "/usr/local/lib/python3.12/socket.py", line 838, in create_connection
    sock.connect(sa)
ConnectionRefusedError: [Errno 111] Connection refused

During handling of the above exception, another exception occurred:

Traceback (most recent call last):
  File "/home/airflow/.local/lib/python3.12/site-packages/airflow/models/taskinstance.py", line 877, in _handle_failure
    task_instance.email_alert(error, failure_context["task"])
  File "/home/airflow/.local/lib/python3.12/site-packages/airflow/models/taskinstance.py", line 3163, in email_alert
    _email_alert(task_instance=self, exception=exception, task=task)
  File "/home/airflow/.local/lib/python3.12/site-packages/airflow/models/taskinstance.py", line 1065, in _email_alert
    send_email(task.email, subject, html_content_err)
  File "/home/airflow/.local/lib/python3.12/site-packages/airflow/utils/email.py", line 80, in send_email
    return backend(
           ^^^^^^^^
  File "/home/airflow/.local/lib/python3.12/site-packages/airflow/utils/email.py", line 154, in send_email_smtp
    send_mime_email(e_from=mail_from, e_to=recipients, mime_msg=msg, conn_id=conn_id, dryrun=dryrun)
  File "/home/airflow/.local/lib/python3.12/site-packages/airflow/utils/email.py", line 273, in send_mime_email
    smtp_conn = _get_smtp_connection(smtp_host, smtp_port, smtp_timeout, smtp_ssl)
                ^^^^^^^^^^^^^^^^^^^^^^^^^^^^^^^^^^^^^^^^^^^^^^^^^^^^^^^^^^^^^^^^^^
  File "/home/airflow/.local/lib/python3.12/site-packages/airflow/utils/email.py", line 317, in _get_smtp_connection
    return smtplib.SMTP(host=host, port=port, timeout=timeout)
           ^^^^^^^^^^^^^^^^^^^^^^^^^^^^^^^^^^^^^^^^^^^^^^^^^^^
  File "/usr/local/lib/python3.12/smtplib.py", line 255, in __init__
    (code, msg) = self.connect(host, port)
                  ^^^^^^^^^^^^^^^^^^^^^^^^
  File "/usr/local/lib/python3.12/smtplib.py", line 341, in connect
    self.sock = self._get_socket(host, port, self.timeout)
                ^^^^^^^^^^^^^^^^^^^^^^^^^^^^^^^^^^^^^^^^^^
  File "/usr/local/lib/python3.12/smtplib.py", line 312, in _get_socket
    return socket.create_connection((host, port), timeout,
           ^^^^^^^^^^^^^^^^^^^^^^^^^^^^^^^^^^^^^^^^^^^^^^^
  File "/usr/local/lib/python3.12/socket.py", line 853, in create_connection
    raise exceptions[0]
  File "/usr/local/lib/python3.12/socket.py", line 838, in create_connection
    sock.connect(sa)
ConnectionRefusedError: [Errno 111] Connection refused
[2024-06-14T04:31:03.825+0000] {processor.py:791} INFO - Executed failure callback for <TaskInstance: ETL_toll_data.unzip_data scheduled__2024-06-12T00:00:00+00:00 [failed]> in state failed
[2024-06-14T04:31:03.837+0000] {logging_mixin.py:188} INFO - [2024-06-14T04:31:03.837+0000] {dag.py:3096} INFO - Sync 1 DAGs
[2024-06-14T04:31:03.851+0000] {logging_mixin.py:188} INFO - [2024-06-14T04:31:03.851+0000] {dag.py:3954} INFO - Setting next_dagrun for ETL_toll_data to 2024-06-14 00:00:00+00:00, run_after=2024-06-15 00:00:00+00:00
[2024-06-14T04:31:03.870+0000] {processor.py:183} INFO - Processing /opt/airflow/dags/ETL_toll_data.py took 0.713 seconds
[2024-06-14T04:31:34.631+0000] {processor.py:161} INFO - Started process (PID=632) to work on /opt/airflow/dags/ETL_toll_data.py
[2024-06-14T04:31:34.632+0000] {processor.py:830} INFO - Processing file /opt/airflow/dags/ETL_toll_data.py for tasks to queue
[2024-06-14T04:31:34.634+0000] {logging_mixin.py:188} INFO - [2024-06-14T04:31:34.634+0000] {dagbag.py:545} INFO - Filling up the DagBag from /opt/airflow/dags/ETL_toll_data.py
[2024-06-14T04:31:35.044+0000] {processor.py:840} INFO - DAG(s) 'ETL_toll_data' retrieved from /opt/airflow/dags/ETL_toll_data.py
[2024-06-14T04:31:35.062+0000] {logging_mixin.py:188} INFO - [2024-06-14T04:31:35.061+0000] {taskinstance.py:2907} ERROR - {'DAG Id': 'ETL_toll_data', 'Task Id': 'unzip_data', 'Run Id': 'scheduled__2024-06-10T00:00:00+00:00', 'Hostname': 'af8e208997f1', 'External Executor Id': '0b103bb7-eab8-4be7-aa9a-ca7c018b611c'}
[2024-06-14T04:31:35.074+0000] {logging_mixin.py:188} INFO - [2024-06-14T04:31:35.074+0000] {taskinstance.py:1206} INFO - Marking task as FAILED. dag_id=ETL_toll_data, task_id=unzip_data, run_id=scheduled__2024-06-10T00:00:00+00:00, execution_date=20240610T000000, start_date=20240614T043027, end_date=20240614T043135
[2024-06-14T04:31:35.090+0000] {logging_mixin.py:188} WARNING - /home/airflow/.local/lib/python3.12/site-packages/airflow/utils/email.py:154 RemovedInAirflow3Warning: Fetching SMTP credentials from configuration variables will be deprecated in a future release. Please set credentials using a connection instead.
[2024-06-14T04:31:35.091+0000] {logging_mixin.py:188} INFO - [2024-06-14T04:31:35.091+0000] {configuration.py:1050} WARNING - section/key [smtp/smtp_user] not found in config
[2024-06-14T04:31:35.092+0000] {logging_mixin.py:188} INFO - [2024-06-14T04:31:35.092+0000] {email.py:271} INFO - Email alerting: attempt 1
[2024-06-14T04:31:35.096+0000] {logging_mixin.py:188} INFO - [2024-06-14T04:31:35.096+0000] {configuration.py:1050} WARNING - section/key [smtp/smtp_user] not found in config
[2024-06-14T04:31:35.097+0000] {logging_mixin.py:188} INFO - [2024-06-14T04:31:35.097+0000] {email.py:271} INFO - Email alerting: attempt 1
[2024-06-14T04:31:35.099+0000] {logging_mixin.py:188} INFO - [2024-06-14T04:31:35.097+0000] {taskinstance.py:879} ERROR - Failed to send email to: ['21521333@gm.uit.edu.vn']
Traceback (most recent call last):
  File "/home/airflow/.local/lib/python3.12/site-packages/airflow/models/taskinstance.py", line 1063, in _email_alert
    send_email(task.email, subject, html_content)
  File "/home/airflow/.local/lib/python3.12/site-packages/airflow/utils/email.py", line 80, in send_email
    return backend(
           ^^^^^^^^
  File "/home/airflow/.local/lib/python3.12/site-packages/airflow/utils/email.py", line 154, in send_email_smtp
    send_mime_email(e_from=mail_from, e_to=recipients, mime_msg=msg, conn_id=conn_id, dryrun=dryrun)
  File "/home/airflow/.local/lib/python3.12/site-packages/airflow/utils/email.py", line 273, in send_mime_email
    smtp_conn = _get_smtp_connection(smtp_host, smtp_port, smtp_timeout, smtp_ssl)
                ^^^^^^^^^^^^^^^^^^^^^^^^^^^^^^^^^^^^^^^^^^^^^^^^^^^^^^^^^^^^^^^^^^
  File "/home/airflow/.local/lib/python3.12/site-packages/airflow/utils/email.py", line 317, in _get_smtp_connection
    return smtplib.SMTP(host=host, port=port, timeout=timeout)
           ^^^^^^^^^^^^^^^^^^^^^^^^^^^^^^^^^^^^^^^^^^^^^^^^^^^
  File "/usr/local/lib/python3.12/smtplib.py", line 255, in __init__
    (code, msg) = self.connect(host, port)
                  ^^^^^^^^^^^^^^^^^^^^^^^^
  File "/usr/local/lib/python3.12/smtplib.py", line 341, in connect
    self.sock = self._get_socket(host, port, self.timeout)
                ^^^^^^^^^^^^^^^^^^^^^^^^^^^^^^^^^^^^^^^^^^
  File "/usr/local/lib/python3.12/smtplib.py", line 312, in _get_socket
    return socket.create_connection((host, port), timeout,
           ^^^^^^^^^^^^^^^^^^^^^^^^^^^^^^^^^^^^^^^^^^^^^^^
  File "/usr/local/lib/python3.12/socket.py", line 853, in create_connection
    raise exceptions[0]
  File "/usr/local/lib/python3.12/socket.py", line 838, in create_connection
    sock.connect(sa)
ConnectionRefusedError: [Errno 111] Connection refused

During handling of the above exception, another exception occurred:

Traceback (most recent call last):
  File "/home/airflow/.local/lib/python3.12/site-packages/airflow/models/taskinstance.py", line 877, in _handle_failure
    task_instance.email_alert(error, failure_context["task"])
  File "/home/airflow/.local/lib/python3.12/site-packages/airflow/models/taskinstance.py", line 3163, in email_alert
    _email_alert(task_instance=self, exception=exception, task=task)
  File "/home/airflow/.local/lib/python3.12/site-packages/airflow/models/taskinstance.py", line 1065, in _email_alert
    send_email(task.email, subject, html_content_err)
  File "/home/airflow/.local/lib/python3.12/site-packages/airflow/utils/email.py", line 80, in send_email
    return backend(
           ^^^^^^^^
  File "/home/airflow/.local/lib/python3.12/site-packages/airflow/utils/email.py", line 154, in send_email_smtp
    send_mime_email(e_from=mail_from, e_to=recipients, mime_msg=msg, conn_id=conn_id, dryrun=dryrun)
  File "/home/airflow/.local/lib/python3.12/site-packages/airflow/utils/email.py", line 273, in send_mime_email
    smtp_conn = _get_smtp_connection(smtp_host, smtp_port, smtp_timeout, smtp_ssl)
                ^^^^^^^^^^^^^^^^^^^^^^^^^^^^^^^^^^^^^^^^^^^^^^^^^^^^^^^^^^^^^^^^^^
  File "/home/airflow/.local/lib/python3.12/site-packages/airflow/utils/email.py", line 317, in _get_smtp_connection
    return smtplib.SMTP(host=host, port=port, timeout=timeout)
           ^^^^^^^^^^^^^^^^^^^^^^^^^^^^^^^^^^^^^^^^^^^^^^^^^^^
  File "/usr/local/lib/python3.12/smtplib.py", line 255, in __init__
    (code, msg) = self.connect(host, port)
                  ^^^^^^^^^^^^^^^^^^^^^^^^
  File "/usr/local/lib/python3.12/smtplib.py", line 341, in connect
    self.sock = self._get_socket(host, port, self.timeout)
                ^^^^^^^^^^^^^^^^^^^^^^^^^^^^^^^^^^^^^^^^^^
  File "/usr/local/lib/python3.12/smtplib.py", line 312, in _get_socket
    return socket.create_connection((host, port), timeout,
           ^^^^^^^^^^^^^^^^^^^^^^^^^^^^^^^^^^^^^^^^^^^^^^^
  File "/usr/local/lib/python3.12/socket.py", line 853, in create_connection
    raise exceptions[0]
  File "/usr/local/lib/python3.12/socket.py", line 838, in create_connection
    sock.connect(sa)
ConnectionRefusedError: [Errno 111] Connection refused
[2024-06-14T04:31:35.109+0000] {processor.py:791} INFO - Executed failure callback for <TaskInstance: ETL_toll_data.unzip_data scheduled__2024-06-10T00:00:00+00:00 [failed]> in state failed
[2024-06-14T04:31:35.122+0000] {logging_mixin.py:188} INFO - [2024-06-14T04:31:35.122+0000] {dag.py:3096} INFO - Sync 1 DAGs
[2024-06-14T04:31:35.138+0000] {logging_mixin.py:188} INFO - [2024-06-14T04:31:35.138+0000] {dag.py:3954} INFO - Setting next_dagrun for ETL_toll_data to 2024-06-14 00:00:00+00:00, run_after=2024-06-15 00:00:00+00:00
[2024-06-14T04:31:35.156+0000] {processor.py:183} INFO - Processing /opt/airflow/dags/ETL_toll_data.py took 0.531 seconds
[2024-06-14T04:32:05.902+0000] {processor.py:161} INFO - Started process (PID=692) to work on /opt/airflow/dags/ETL_toll_data.py
[2024-06-14T04:32:05.903+0000] {processor.py:830} INFO - Processing file /opt/airflow/dags/ETL_toll_data.py for tasks to queue
[2024-06-14T04:32:05.905+0000] {logging_mixin.py:188} INFO - [2024-06-14T04:32:05.905+0000] {dagbag.py:545} INFO - Filling up the DagBag from /opt/airflow/dags/ETL_toll_data.py
[2024-06-14T04:32:06.322+0000] {processor.py:840} INFO - DAG(s) 'ETL_toll_data' retrieved from /opt/airflow/dags/ETL_toll_data.py
[2024-06-14T04:32:06.337+0000] {logging_mixin.py:188} INFO - [2024-06-14T04:32:06.337+0000] {dag.py:3096} INFO - Sync 1 DAGs
[2024-06-14T04:32:06.352+0000] {logging_mixin.py:188} INFO - [2024-06-14T04:32:06.352+0000] {dag.py:3954} INFO - Setting next_dagrun for ETL_toll_data to 2024-06-14 00:00:00+00:00, run_after=2024-06-15 00:00:00+00:00
[2024-06-14T04:32:06.376+0000] {processor.py:183} INFO - Processing /opt/airflow/dags/ETL_toll_data.py took 0.481 seconds
